Workbook

Sheet Sheet1
A1: name | B1: Country | C1: wikipedia_language | D1: page_title | E1: page_url | F1: wikipedia_content_html | G1: wikipedia_content_wikitext
A2: BARBAGALLO Giovanni | B2: =INDEX(Sheet2!$D$2:$D$1210,MATCH(Sheet1!A2,Sheet2!$B$2:$B$1210,0)) -> IT
A3: CRUZ Joaquim | B3: =INDEX(Sheet2!$D$2:$D$1210,MATCH(Sheet1!A3,Sheet2!$B$2:$B$1210,0)) -> PT
A4: DIETRICH Roberto | B4: =INDEX(Sheet2!$D$2:$D$1210,MATCH(Sheet1!A4,Sheet2!$B$2:$B$1210,0)) -> RO
A5: GKIKOPOULOS Georgios | B5: =INDEX(Sheet2!$D$2:$D$1210,MATCH(Sheet1!A5,Sheet2!$B$2:$B$1210,0)) -> GR
A6: HIDVÉGHI Balázs | B6: =INDEX(Sheet2!$D$2:$D$1210,MATCH(Sheet1!A6,Sheet2!$B$2:$B$1210,0)) -> HU
A7: KARI Rina Ronja | B7: =INDEX(Sheet2!$D$2:$D$1210,MATCH(Sheet1!A7,Sheet2!$B$2:$B$1210,0)) -> DK
A8: KOEWIUS Annette | B8: =INDEX(Sheet2!$D$2:$D$1210,MATCH(Sheet1!A8,Sheet2!$B$2:$B$1210,0)) -> DE
A9: REVAULT D'ALLONNES BONNEFOY Christine | B9: =INDEX(Sheet2!$D$2:$D$1210,MATCH(Sheet1!A9,Sheet2!$B$2:$B$1210,0)) -> FR
A10: ABELA BALDACCHINO Claudette | B10: =INDEX(Sheet2!$D$2:$D$1210,MATCH(Sheet1!A10,Sheet2!$B$2:$B$1210,0)) -> MT
A11: BALDINI Marino | B11: =INDEX(Sheet2!$D$2:$D$1210,MATCH(Sheet1!A11,Sheet2!$B$2:$B$1210,0)) -> HR
A12: BERTOT Fabrizio | B12: =INDEX(Sheet2!$D$2:$D$1210,MATCH(Sheet1!A12,Sheet2!$B$2:$B$1210,0)) -> IT
A13: BONANINI Franco | B13: =INDEX(Sheet2!$D$2:$D$1210,MATCH(Sheet1!A13,Sheet2!$B$2:$B$1210,0)) -> IT
... A86: STADLER Ewald | B86: =INDEX(Sheet2!$D$2:$D$1210,MATCH(Sheet1!A86,Sheet2!$B$2:$B$1210,0)) -> AT
A87: TERHO Sampo | B87: FI
A88: TREMATERRA Gino | B88: =INDEX(Sheet2!$D$2:$D$1210,MATCH(Sheet1!A88,Sheet2!$B$2:$B$1210,0)) -> IT
A89: WEIDENHOLZER Josef | B89: =INDEX(Sheet2!$D$2:$D$1210,MATCH(Sheet1!A89,Sheet2!$B$2:$B$1210,0)) -> AT
A90: ZANONI Andrea | B90: =INDEX(Sheet2!$D$2:$D$1210,MATCH(Sheet1!A90,Sheet2!$B$2:$B$1210,0)) -> IT
A91: ZIJLSTRA Auke | B91: =INDEX(Sheet2!$D$2:$D$1210,MATCH(Sheet1!A91,Sheet2!$B$2:$B$1210,0)) -> NL
A92: BOULLAND Philippe | B92: =INDEX(Sheet2!$D$2:$D$1210,MATCH(Sheet1!A92,Sheet2!$B$2:$B$1210,0)) -> FR
A93: GÁLL-PELCZ Ildikó | B93: =INDEX(Sheet2!$D$2:$D$1210,MATCH(Sheet1!A93,Sheet2!$B$2:$B$1210,0)) -> HU
A94: GUTIÉRREZ PRIETO Sergio | B94: =INDEX(Sheet2!$D$2:$D$1210,MATCH(Sheet1!A94,Sheet2!$B$2:$B$1210,0)) -> ES
A95: HARTONG Lucas | B95: =INDEX(Sheet2!$D$2:$D$1210,MATCH(Sheet1!A95,Sheet2!$B$2:$B$1210,0)) -> NL
A96: IRIGOYEN PÉREZ María | B96: =INDEX(Sheet2!$D$2:$D$1210,MATCH(Sheet1!A96,Sheet2!$B$2:$B$1210,0)) -> ES
A97: KOVÁCS Béla | B97: =INDEX(Sheet2!$D$2:$D$1210,MATCH(Sheet1!A97,Sheet2!$B$2:$B$1210,0)) -> HU
A98: KOZŁOWSKI Jan | B98: =INDEX(Sheet2!$D$2:$D$1210,MATCH(Sheet1!A98,Sheet2!$B$2:$B$1210,0)) -> PL
A99: LE GRIP Constance | B99: =INDEX(Sheet2!$D$2:$D$1210,MATCH(Sheet1!A99,Sheet2!$B$2:$B$1210,0)) -> FR
... A876: MAYER Alex | B876: =INDEX(Sheet2!$D$2:$D$1210,MATCH(Sheet1!A876,Sheet2!$B$2:$B$1210,0)) -> GB
A877: MAYER Georg | B877: AT
A878: MAZURONIS Valentinas | B878: =INDEX(Sheet2!$D$2:$D$1210,MATCH(Sheet1!A878,Sheet2!$B$2:$B$1210,0)) -> LT
A879: McALLISTER David | B879: =INDEX(Sheet2!$D$2:$D$1210,MATCH(Sheet1!A879,Sheet2!$B$2:$B$1210,0)) -> DE
A880: McAVAN Linda | B880: =INDEX(Sheet2!$D$2:$D$1210,MATCH(Sheet1!A880,Sheet2!$B$2:$B$1210,0)) -> GB
A881: McCLARKIN Emma | B881: =INDEX(Sheet2!$D$2:$D$1210,MATCH(Sheet1!A881,Sheet2!$B$2:$B$1210,0)) -> GB
A882: McGUINNESS Mairead | B882: =INDEX(Sheet2!$D$2:$D$1210,MATCH(Sheet1!A882,Sheet2!$B$2:$B$1210,0)) -> IE
A883: McINTYRE Anthea | B883: =INDEX(Sheet2!$D$2:$D$1210,MATCH(Sheet1!A883,Sheet2!$B$2:$B$1210,0)) -> GB
A884: MEISSNER Gesine | B884: =INDEX(Sheet2!$D$2:$D$1210,MATCH(Sheet1!A884,Sheet2!$B$2:$B$1210,0)) -> DE
A885: MÉLIN Joëlle | B885: =INDEX(Sheet2!$D$2:$D$1210,MATCH(Sheet1!A885,Sheet2!$B$2:$B$1210,0)) -> FR
A886: MELIOR Susanne | B886: =INDEX(Sheet2!$D$2:$D$1210,MATCH(Sheet1!A886,Sheet2!$B$2:$B$1210,0)) -> DE
A887: MELO Nuno | B887: =INDEX(Sheet2!$D$2:$D$1210,MATCH(Sheet1!A887,Sheet2!$B$2:$B$1210,0)) -> PT
A888: MESSERSCHMIDT Morten | B888: =INDEX(Sheet2!$D$2:$D$1210,MATCH(Sheet1!A888,Sheet2!$B$2:$B$1210,0)) -> DK
...

Sheet Sheet2
A1: Name | D1: Country | E1: National party | F1: Political Group | G1: Term start | H1: Term end | I1: Year Start
A2: BARBAGALLO Giovanni | B2: =A2 -> BARBAGALLO Giovanni | C2: =RIGHT(A2,LEN(A2)-FIND("@",SUBSTITUTE(A2," ","@",LEN(A2)-LEN(SUBSTITUTE(A2," ",""))))) -> Giovanni | D2: IT | E2: PD | F2: S&D | G2: 11.03.2014 | H2: 30.06.2014 | I2: 2014
A3: CRUZ Joaquim | B3: =A3 -> CRUZ Joaquim | C3: =RIGHT(A3,LEN(A3)-FIND("@",SUBSTITUTE(A3," ","@",LEN(A3)-LEN(SUBSTITUTE(A3," ",""))))) -> Joaquim | D3: PT | E3: PSD | F3: PPE | G3: 01.05.2014 | H3: 30.06.2014 | I3: 2014
A4: DIETRICH Roberto | B4: =A4 -> DIETRICH Roberto | C4: =RIGHT(A4,LEN(A4)-FIND("@",SUBSTITUTE(A4," ","@",LEN(A4)-LEN(SUBSTITUTE(A4," ",""))))) -> Roberto | D4: RO | E4: PNL | F4: ALDE | G4: 11.06.2014 | H4: 30.06.2014 | I4: 2014
A5: GKIKOPOULOS Georgios | B5: =A5 -> GKIKOPOULOS Georgios | C5: =RIGHT(A5,LEN(A5)-FIND("@",SUBSTITUTE(A5," ","@",LEN(A5)-LEN(SUBSTITUTE(A5," ",""))))) -> Georgios | D5: GR | E5: KKE | F5: GUE/NGL | G5: 19.05.2014 | H5: 30.06.2014 | I5: 2014
A6: HIDVÉGHI Balázs | B6: =A6 -> HIDVÉGHI Balázs | C6: =RIGHT(A6,LEN(A6)-FIND("@",SUBSTITUTE(A6," ","@",LEN(A6)-LEN(SUBSTITUTE(A6," ",""))))) -> Balázs | D6: HU | E6: Fidesz-KDNP | F6: PPE | G6: 15.05.2014 | H6: 30.06.2014 | I6: 2014
A7: KARI Rina Ronja | B7: =A7 -> KARI Rina Ronja | C7: =RIGHT(A7,LEN(A7)-FIND("@",SUBSTITUTE(A7," ","@",LEN(A7)-LEN(SUBSTITUTE(A7," ",""))))) -> Ronja | D7: DK | E7: N | F7: GUE/NGL | G7: 05.02.2014 | I7: 2014
A8: KOEWIUS Annette | B8: =A8 -> KOEWIUS Annette | C8: =RIGHT(A8,LEN(A8)-FIND("@",SUBSTITUTE(A8," ","@",LEN(A8)-LEN(SUBSTITUTE(A8," ",""))))) -> Annette | D8: DE | E8: CDU | F8: PPE | G8: 12.03.2014 | H8: 30.06.2014 | I8: 2014
A9: REVAULT D'ALLONNES BONNEFOY Christine | B9: =A9 -> REVAULT D'ALLONNES BONNEFOY Christine | C9: =RIGHT(A9,LEN(A9)-FIND("@",SUBSTITUTE(A9," ","@",LEN(A9)-LEN(SUBSTITUTE(A9," ",""))))) -> Christine | D9: FR | E9: PS | F9: S&D | G9: 09.04.2014 | I9: 2014
A10: ABELA BALDACCHINO Claudette | B10: =A10 -> ABELA BALDACCHINO Claudette | C10: =RIGHT(A10,LEN(A10)-FIND("@",SUBSTITUTE(A10," ","@",LEN(A10)-LEN(SUBSTITUTE(A10," ",""))))) -> Claudette | D10: MT | E10: MLP | F10: S&D | G10: 25.04.2013 | H10: 30.06.2014 | I10: 2013
A11: BALDINI Marino | B11: =A11 -> BALDINI Marino | C11: =RIGHT(A11,LEN(A11)-FIND("@",SUBSTITUTE(A11," ","@",LEN(A11)-LEN(SUBSTITUTE(A11," ",""))))) -> Marino | D11: HR | E11: SDP | F11: S&D | G11: 01.07.2013 | H11: 30.06.2014 | I11: 2013
A12: BERTOT Fabrizio | B12: =A12 -> BERTOT Fabrizio | C12: =RIGHT(A12,LEN(A12)-FIND("@",SUBSTITUTE(A12," ","@",LEN(A12)-LEN(SUBSTITUTE(A12," ",""))))) -> Fabrizio | D12: IT | E12: Forza Italia | F12: PPE | G12: 12.04.2013 | H12: 30.06.2014 | I12: 2013
A13: BONANINI Franco | B13: =A13 -> BONANINI Franco | C13: =RIGHT(A13,LEN(A13)-FIND("@",SUBSTITUTE(A13," ","@",LEN(A13)-LEN(SUBSTITUTE(A13," ",""))))) -> Franco | D13: IT | E13: Ind. | F13: NI | G13: 12.04.2013 | H13: 30.06.2014 | I13: 2013
A14: BORISSOV Preslav | B14: =A14 -> BORISSOV Preslav | C14: =RIGHT(A14,LEN(A14)-FIND("@",SUBSTITUTE(A14," ","@",LEN(A14)-LEN(SUBSTITUTE(A14," ",""))))) -> Preslav | D14: BG | E14: GERB | F14: PPE | G14: 01.01.2013 | H14: 30.06.2014 | I14: 2013
A15: BORZAN Biljana | B15: =A15 -> BORZAN Biljana | C15: =RIGHT(A15,LEN(A15)-FIND("@",SUBSTITUTE(A15," ","@",LEN(A15)-LEN(SUBSTITUTE(A15," ",""))))) -> Biljana | D15: HR | E15: SDP | F15: S&D | G15: 01.07.2013 | I15: 2013
A16: BUŠIĆ Zdravka | B16: =A16 -> BUŠIĆ Zdravka | C16: =RIGHT(A16,LEN(A16)-FIND("@",SUBSTITUTE(A16," ","@",LEN(A16)-LEN(SUBSTITUTE(A16," ",""))))) -> Zdravka | D16: HR | E16: HDZ | F16: PPE | G16: 01.07.2013 | H16: 30.06.2014 | I16: 2013
A17: DE MARTINI Susy | B17: =A17 -> DE MARTINI Susy | C17: =RIGHT(A17,LEN(A17)-FIND("@",SUBSTITUTE(A17," ","@",LEN(A17)-LEN(SUBSTITUTE(A17," ",""))))) -> Susy | D17: IT | E17: Forza Italia | F17: ECR | G17: 12.04.2013 | H17: 30.06.2014 | I17: 2013
A18: DEMESMAEKER Mark | B18: =A18 -> DEMESMAEKER Mark | C18: =RIGHT(A18,LEN(A18)-FIND("@",SUBSTITUTE(A18," ","@",LEN(A18)-LEN(SUBSTITUTE(A18," ",""))))) -> Mark | D18: BE | E18: N-VA | F18: Verts/ALE | G18: 01.02.2013 | I18: 2013
A19: FRIGO Franco | B19: =A19 -> FRIGO Franco | C19: =RIGHT(A19,LEN(A19)-FIND("@",SUBSTITUTE(A19," ","@",LEN(A19)-LEN(SUBSTITUTE(A19," ",""))))) -> Franco | D19: IT | E19: PD | F19: S&D | G19: 07.05.2013 | H19: 30.06.2014 | I19: 2013
A20: IRAZABALBEITIA FERNÁNDEZ Iñaki | B20: =A20 -> IRAZABALBEITIA FERNÁNDEZ Iñaki | C20: =RIGHT(A20,LEN(A20)-FIND("@",SUBSTITUTE(A20," ","@",LEN(A20)-LEN(SUBSTITUTE(A20," ",""))))) -> Iñaki | D20: ES | E20: Aralar | F20: Verts/ALE | G20: 11.07.2013 | H20: 30.06.2014 | I20: 2013
A21: LARSEN-JENSEN Claus | B21: =A21 -> LARSEN-JENSEN Claus | C21: =RIGHT(A21,LEN(A21)-FIND("@",SUBSTITUTE(A21," ","@",LEN(A21)-LEN(SUBSTITUTE(A21," ",""))))) -> Claus | D21: DK | E21: A | F21: S&D | G21: 13.12.2013 | H21: 30.06.2014 | I21: 2013
A22: MALETIĆ Ivana | B22: =A22 -> MALETIĆ Ivana | C22: =RIGHT(A22,LEN(A22)-FIND("@",SUBSTITUTE(A22," ","@",LEN(A22)-LEN(SUBSTITUTE(A22," ",""))))) -> Ivana | D22: HR | E22: HDZ | F22: PPE | G22: 01.07.2013 | I22: 2013
A23: METSOLA Roberta | B23: =A23 -> METSOLA Roberta | C23: =RIGHT(A23,LEN(A23)-FIND("@",SUBSTITUTE(A23," ","@",LEN(A23)-LEN(SUBSTITUTE(A23," ",""))))) -> Roberta | D23: MT | E23: PN | F23: PPE | G23: 25.04.2013 | I23: 2013
A24: MICHELS Martina | B24: =A24 -> MICHELS Martina | C24: =RIGHT(A24,LEN(A24)-FIND("@",SUBSTITUTE(A24," ","@",LEN(A24)-LEN(SUBSTITUTE(A24," ",""))))) -> Martina | D24: DE | E24: DIE LINKE. | F24: GUE/NGL | G24: 05.09.2013 | I24: 2013
A25: MIZZI Marlene | B25: =A25 -> MIZZI Marlene | C25: =RIGHT(A25,LEN(A25)-FIND("@",SUBSTITUTE(A25," ","@",LEN(A25)-LEN(SUBSTITUTE(A25," ",""))))) -> Marlene | D25: MT | E25: MLP | F25: S&D | G25: 25.04.2013 | I25: 2013
A26: PETROVIĆ JAKOVINA Sandra | B26: =A26 -> PETROVIĆ JAKOVINA Sandra | C26: =RIGHT(A26,LEN(A26)-FIND("@",SUBSTITUTE(A26," ","@",LEN(A26)-LEN(SUBSTITUTE(A26," ",""))))) -> Sandra | D26: HR | E26: SDP | F26: S&D | G26: 01.07.2013 | H26: 30.06.2014 | I26: 2013
A27: PICULA Tonino | B27: =A27 -> PICULA Tonino | C27: =RIGHT(A27,LEN(A27)-FIND("@",SUBSTITUTE(A27," ","@",LEN(A27)-LEN(SUBSTITUTE(A27," ",""))))) -> Tonino | D27: HR | E27: SDP | F27: S&D | G27: 01.07.2013 | I27: 2013
A28: PITSILLIDES Andreas | B28: =A28 -> PITSILLIDES Andreas | C28: =RIGHT(A28,LEN(A28)-FIND("@",SUBSTITUTE(A28," ","@",LEN(A28)-LEN(SUBSTITUTE(A28," ",""))))) -> Andreas | D28: CY | E28: DI.SY | F28: PPE | G28: 04.03.2013 | H28: 30.06.2014 | I28: 2013
A29: PLENKOVIĆ Andrej | B29: =A29 -> PLENKOVIĆ Andrej | C29: =RIGHT(A29,LEN(A29)-FIND("@",SUBSTITUTE(A29," ","@",LEN(A29)-LEN(SUBSTITUTE(A29," ",""))))) -> Andrej | D29: HR | E29: HDZ | F29: PPE | G29: 01.07.2013 | I29: 2013
A30: ROSS Tadeusz | B30: =A30 -> ROSS Tadeusz | C30: =RIGHT(A30,LEN(A30)-FIND("@",SUBSTITUTE(A30," ","@",LEN(A30)-LEN(SUBSTITUTE(A30," ",""))))) -> Tadeusz | D30: PL | E30: PO | F30: PPE | G30: 17.12.2013 | H30: 30.06.2014 | I30: 2013
A31: STIER Davor Ivo | B31: =A31 -> STIER Davor Ivo | C31: =RIGHT(A31,LEN(A31)-FIND("@",SUBSTITUTE(A31," ","@",LEN(A31)-LEN(SUBSTITUTE(A31," ",""))))) -> Ivo | D31: HR | E31: HDZ | F31: PPE | G31: 01.07.2013 | I31: 2013
A32: ŠUICA Dubravka | B32: =A32 -> ŠUICA Dubravka | C32: =RIGHT(A32,LEN(A32)-FIND("@",SUBSTITUTE(A32," ","@",LEN(A32)-LEN(SUBSTITUTE(A32," ",""))))) -> Dubravka | D32: HR | E32: HDZ | F32: PPE | G32: 01.07.2013 | I32: 2013
A33: TOMAŠIĆ Ruža | B33: =A33 -> TOMAŠIĆ Ruža | C33: =RIGHT(A33,LEN(A33)-FIND("@",SUBSTITUTE(A33," ","@",LEN(A33)-LEN(SUBSTITUTE(A33," ",""))))) -> Ruža | D33: HR | E33: HSP AS | F33: ECR | G33: 01.07.2013 | I33: 2013
A34: VALJALO Oleg | B34: =A34 -> VALJALO Oleg | C34: =RIGHT(A34,LEN(A34)-FIND("@",SUBSTITUTE(A34," ","@",LEN(A34)-LEN(SUBSTITUTE(A34," ",""))))) -> Oleg | D34: HR | E34: SDP | F34: S&D | G34: 01.07.2013 | H34: 30.06.2014 | I34: 2013
A35: VULJANIĆ Nikola | B35: =A35 -> VULJANIĆ Nikola | C35: =RIGHT(A35,LEN(A35)-FIND("@",SUBSTITUTE(A35," ","@",LEN(A35)-LEN(SUBSTITUTE(A35," ",""))))) -> Nikola | D35: HR | E35: HL | F35: GUE/NGL | G35: 01.07.2013 | H35: 30.06.2014 | I35: 2013
A36: ZAMFIRESCU Dan Dumitru | B36: =A36 -> ZAMFIRESCU Dan Dumitru | C36: =RIGHT(A36,LEN(A36)-FIND("@",SUBSTITUTE(A36," ","@",LEN(A36)-LEN(SUBSTITUTE(A36," ",""))))) -> Dumitru | D36: RO | E36: PRM | F36: NI | G36: 09.01.2013 | H36: 30.06.2014 | I36: 2013
A37: ANDERSON Martina | B37: =A37 -> ANDERSON Martina | C37: Martina | D37: GB | E37: SF | F37: GUE/NGL | G37: 12.06.2012 | I37: 2012
A38: ANDRIEU Eric | B38: =A38 -> ANDRIEU Eric | C38: =RIGHT(A38,LEN(A38)-FIND("@",SUBSTITUTE(A38," ","@",LEN(A38)-LEN(SUBSTITUTE(A38," ",""))))) -> Eric | D38: FR | E38: PS | F38: S&D | G38: 16.05.2012 | I38: 2012
A39: BÁNKI Erik | B39: =A39 -> BÁNKI Erik | C39: =RIGHT(A39,LEN(A39)-FIND("@",SUBSTITUTE(A39," ","@",LEN(A39)-LEN(SUBSTITUTE(A39," ",""))))) -> Erik | D39: HU | E39: Fidesz-KDNP | F39: PPE | G39: 01.06.2012 | H39: 05.05.2014 | I39: 2012
A40: BARRACCIU Francesca | B40: =A40 -> BARRACCIU Francesca | C40: =RIGHT(A40,LEN(A40)-FIND("@",SUBSTITUTE(A40," ","@",LEN(A40)-LEN(SUBSTITUTE(A40," ",""))))) -> Francesca | D40: IT | E40: PD | F40: S&D | G40: 17.12.2012 | H40: 27.02.2014 | I40: 2012
...
